Workbook

Sheet POLIGONAL MINIMOS
F2: POLIGONAL CERRADA
F5: PROYECTO: | H5: POLIGONAL CERRADA U DISTRITAL SEDE VIVERO, AJUSTE POR MÍNIMOS CUADRADOS
F7: TOPOGRAFO: | H7: GRUPO DE TRABAJO 3
F8: DIRECCIÓN: | H8: CRA 5 #15-82, SEDE VIVERO
D10: FECHA: | E10: AÑO | G10: MES | H10: DIA | I10: HOJA: | J10: 1 | K10: DE | L10: 1
E11: 2021 | G11: 11 | H11: 4
D13: Delta | E13: Punto | F13: Ang. Ext | G13: Azimut | H13: Dist. Horz. | I13: Proy. (N-S) | J13: Proy. (E-W) | K13: C. NORTE | L13: C. ESTE | M13: COSENO | N13: SENO
E14: 14_IS1 | G14: 35.002228
D15: Famarena_5 | K15: 100139.84 | L15: 101491.44
D16: D1 | F16: 97.775556 | G16: 132.77778 | H16: 32.957 | I16: =M16*H16 | J16: =N16*H16 | K16: =K15+I16 | L16: =L15+J16 | M16: =COS(RADIANS(G16)) | N16: =SIN(RADIANS(G16))
D17: D2 | F17: 155.38694 | G17: 108.16506 | H17: 13.76 | I17: =M17*H17 | J17: =N17*H17 | K17: =K16+I17 | L17: =L16+J17 | M17: =COS(RADIANS(G17)) | N17: =SIN(RADIANS(G17))
D18: D3 | F18: 109.37778 | G18: 37.543 | H18: 87.103 | I18: =M18*H18 | J18: =N18*H18 | K18: =K17+I18 | L18: =L17+J18 | M18: =COS(RADIANS(G18)) | N18: =SIN(RADIANS(G18))
D19: D4 | F19: 79.267222 | G19: 296.81039 | H19: 25.846 | I19: =M19*H19 | J19: =N19*H19 | K19: =K18+I19 | L19: =L18+J19 | M19: =COS(RADIANS(G19)) | N19: =SIN(RADIANS(G19))
D20: Famarena_5 | F20: 114.40389 | G20: 231.21362 | H20: 86.295 | I20: =M20*H20 | J20: =N20*H20 | K20: =K19+I20 | L20: =L19+J20 | M20: =COS(RADIANS(G20)) | N20: =SIN(RADIANS(G20))
E21: D1 | F21: 81.563056 | G21: 132.77667 | H21: 32.956 | I21: =M21*H21 | J21: =N21*H21 | K21: =K20+I21 | L21: =L20+J21 | M21: =COS(RADIANS(G21)) | N21: =SIN(RADIANS(G21))
G22: =G16-G21
E24: ∑= Ang | F24: =SUM(F17:F21) | H24: ∑= Proyec | I24: =SUM(I17:I21) | J24: =SUM(J17:J21)
E25: e Teorico | F25: =(5-2)*180
E26: e = | F26: =F24-F25 | G26: =RADIANS(F26)
F27: 3 | G27: segundos | I27: =INT(G22) | J27: =INT(((G22-I27)*60)) | K27: =INT(((G22-I27)*60-J27)*60)
B29: M-CONDICIÓN
B30: Angulos | I30: Distancias
B31: 1 | C31: 1 | D31: 1 | E31: 1 | F31: 1 | G31: 1 | H31: 1 | I31: 0 | J31: 0 | K31: 0 | L31: 0 | M31: 0 | N31: 0
B32: =SUM(J16:J21)*-1 | C32: =SUM(J17:J21)*-1 | D32: =SUM(J18:J21)*-1 | E32: =+SUM(J19:J21)*-1 | F32: =+SUM(J20:J21)*-1 | G32: =SUM(J21)*-1 | H32: 0 | I32: =M16 | J32: =+M17 | K32: =+M18 | L32: =+M19 | M32: =+M20 | N32: =+M21
B33: =SUM(I16:I21) | C33: =SUM(I17:I21) | D33: =+SUM(I18:I21) | E33: =+SUM(I19:I21) | F33: =SUM(I20:I21) | G33: =I21 | H33: 0 | I33: =N16 | J33: =+N17 | K33: =+N18 | L33: =+N19 | M33: =+N20 | N33: =+N21
B35: ponderacion ang | E35: Ponderacion de distancias | H35: k matriz de errores
B36: K-Ang | C36: =360*60*60/(2*PI()) | E36: # Med | F36: 2 | H36: e-ang | I36: =G26*-1
B37: presci | C37: 2 | E37: Error | F37: 0.011 | H37: e-pn | I37: =I24*-1
B38: pon_ang | C38: =C36/C37 | E38: Pon_dis | F38: =+SQRT(F36)/F37 | H38: e-pe | I38: =J24*-1
B41: Matris A
B42: Angulos | I42: Distancias
B43: =B31/$C$38 | C43: =C31/$C$38 | D43: =D31/$C$38 | E43: =E31/$C$38 | F43: =F31/$C$38 | G43: =G31/$C$38 | H43: =H31/$C$38 | I43: =I31/$F$38 | J43: =J31/$F$38 | K43: =K31/$F$38 | L43: =L31/$F$38 | M43: =M31/$F$38 | N43: =N31/$F$38
B44: =B32/$C$38 | C44: =C32/$C$38 | D44: =D32/$C$38 | E44: =E32/$C$38 | F44: =F32/$C$38 | G44: =G32/$C$38 | H44: =H32/$C$38 | I44: =I32/$F$38 | J44: =J32/$F$38 | K44: =K32/$F$38 | L44: =L32/$F$38 | M44: =M32/$F$38 | N44: =N32/$F$38
B45: =B33/$C$38 | C45: =C33/$C$38 | D45: =D33/$C$38 | E45: =E33/$C$38 | F45: =F33/$C$38 | G45: =G33/$C$38 | H45: =H33/$C$38 | I45: =I33/$F$38 | J45: =J33/$F$38 | K45: =K33/$F$38 | L45: =L33/$F$38 | M45: =M33/$F$38 | N45: =N33/$F$38
C47: A-trans | G47: Matriz B | K47: R=AT*C | L47: ponderacion | N47: Converción | P47: =SUM(N48:N54) | Q47: Debe llegar al error angular
C48: {=TRANSPOSE(B43:N45)} | D48: -0.00023462734 | E48: -0.00021710083 | G48: {=MMULT(B43:N45,C48:E60)} | H48: 6.9470795e-09 | I48: -1.7084541e-08 | K48: {=MMULT(C48:E60,H58:H60)} | L48: =K48/$C$38 | N48: =DEGREES(L48)
C49: 9.6962736e-06 | D49: -7.2387167e-08 | E49: -6.9442897e-08 | G49: 6.9470795e-09 | H49: 0.00013648606 | I49: -4.4426835e-05 | K49: 0.27567605 | L49: =K49/$C$38 | N49: =DEGREES(L49)
C50: 9.6962736e-06 | D50: 0.00012669896 | E50: 4.1525199e-05 | G50: -1.7084541e-08 | H50: -4.4426835e-05 | I50: 0.00022826567 | K50: 0.28031821 | L50: =K50/$C$38 | N50: =DEGREES(L50)
C51: 9.6962736e-06 | D51: 0.00064134608 | E51: -0.00062813477 | K51: 0.31764693 | L51: =K51/$C$38 | N51: =DEGREES(L51)
C52: 9.6962736e-06 | D52: 0.00041767574 | E52: -0.0007411697 | G52: B-INV | K52: 0.31033041 | L52: =K52/$C$38 | N52: =DEGREES(L52)
...

Sheet AJUSTE CORREGIDO
A1: AJUSTE POR ECUACIONES DE CONDICIÓN — VERSIÓN CORREGIDA
A2: La hoja original declara 7 incógnitas angulares para una cartera de 6 ángulos, y no satisface ninguna de sus tres condiciones.
A3: Modelo correcto: 5 ángulos interiores + 5 distancias, 3 condiciones. El de orientación no entra: un error suyo rota el polígono y no afecta al cierre.
A4: El ángulo interior del vértice j fija el azimut del lado SIGUIENTE, así que el del último vértice no arrastra ningún lado de esta vuelta: entra solo en la condición angular.
A6: OBSERVACIONES
A7: Lado / vértice | B7: Áng. interior (°) | C7: Azimut obs. (°) | D7: Distancia (m) | E7: ΔN | F7: ΔE
A8: D1 | B8: ='POLIGONAL MINIMOS'!F17 | C8: ='POLIGONAL MINIMOS'!G16 | D8: ='POLIGONAL MINIMOS'!H16 | E8: =D8*COS(RADIANS(C8)) | F8: =D8*SIN(RADIANS(C8))
A9: D2 | B9: ='POLIGONAL MINIMOS'!F18 | C9: ='POLIGONAL MINIMOS'!G17 | D9: ='POLIGONAL MINIMOS'!H17 | E9: =D9*COS(RADIANS(C9)) | F9: =D9*SIN(RADIANS(C9))
A10: D3 | B10: ='POLIGONAL MINIMOS'!F19 | C10: ='POLIGONAL MINIMOS'!G18 | D10: ='POLIGONAL MINIMOS'!H18 | E10: =D10*COS(RADIANS(C10)) | F10: =D10*SIN(RADIANS(C10))
A11: D4 | B11: ='POLIGONAL MINIMOS'!F20 | C11: ='POLIGONAL MINIMOS'!G19 | D11: ='POLIGONAL MINIMOS'!H19 | E11: =D11*COS(RADIANS(C11)) | F11: =D11*SIN(RADIANS(C11))
A12: Famarena_5 | B12: ='POLIGONAL MINIMOS'!F21 | C12: ='POLIGONAL MINIMOS'!G20 | D12: ='POLIGONAL MINIMOS'!H20 | E12: =D12*COS(RADIANS(C12)) | F12: =D12*SIN(RADIANS(C12))
A13: Σ | B13: =SUM(B8:B12) | D13: =SUM(D8:D12) | E13: =SUM(E8:E12) | F13: =SUM(F8:F12)
A15: DISCREPANCIAS (w)
A16: angular (") | B16: =(B13-540)*3600
A17: cierre N (m) | B17: =E13
A18: cierre E (m) | B18: =F13
A19: ρ ("/rad) | B19: =180/PI()*3600
A21: MATRIZ DE CONDICIÓN A
B22: v.áng 1 | C22: v.áng 2 | D22: v.áng 3 | E22: v.áng 4 | F22: v.áng 5 | G22: v.dist 1 | H22: v.dist 2 | I22: v.dist 3 | J22: v.dist 4 | K22: v.dist 5
A23: angular | B23: 1 | C23: 1 | D23: 1 | E23: 1 | F23: 1 | G23: 0 | H23: 0 | I23: 0 | J23: 0 | K23: 0
A24: cierre N | B24: =-SUM($F$8:$F$12)/$B$19 | C24: =-SUM($F$9:$F$12)/$B$19 | D24: =-SUM($F$10:$F$12)/$B$19 | E24: =-SUM($F$11:$F$12)/$B$19 | F24: 0 | G24: =COS(RADIANS(C8)) | H24: =COS(RADIANS(C9)) | I24: =COS(RADIANS(C10)) | J24: =COS(RADIANS(C11)) | K24: =COS(RADIANS(C12))
A25: cierre E | B25: =SUM($E$8:$E$12)/$B$19 | C25: =SUM($E$9:$E$12)/$B$19 | D25: =SUM($E$10:$E$12)/$B$19 | E25: =SUM($E$11:$E$12)/$B$19 | F25: 0 | G25: =SIN(RADIANS(C8)) | H25: =SIN(RADIANS(C9)) | I25: =SIN(RADIANS(C10)) | J25: =SIN(RADIANS(C11)) | K25: =SIN(RADIANS(C12))
A27: COFACTORES Q = σ² (σ ang = 2" · σ dist = 0.011 m, los de la hoja original)
B28: =2^2 | C28: =2^2 | D28: =2^2 | E28: =2^2 | F28: =2^2 | G28: =0.011^2 | H28: =0.011^2 | I28: =0.011^2 | J28: =0.011^2 | K28: =0.011^2
A30: M = A·Q·Aᵀ
B31: =SUMPRODUCT($B$23:$K$23,$B$28:$K$28,$B$23:$K$23) | C31: =SUMPRODUCT($B$23:$K$23,$B$28:$K$28,$B$24:$K$24) | D31: =SUMPRODUCT($B$23:$K$23,$B$28:$K$28,$B$25:$K$25)
B32: =SUMPRODUCT($B$24:$K$24,$B$28:$K$28,$B$23:$K$23) | C32: =SUMPRODUCT($B$24:$K$24,$B$28:$K$28,$B$24:$K$24) | D32: =SUMPRODUCT($B$24:$K$24,$B$28:$K$28,$B$25:$K$25)
B33: =SUMPRODUCT($B$25:$K$25,$B$28:$K$28,$B$23:$K$23) | C33: =SUMPRODUCT($B$25:$K$25,$B$28:$K$28,$B$24:$K$24) | D33: =SUMPRODUCT($B$25:$K$25,$B$28:$K$28,$B$25:$K$25)
A35: det(M) | B35: =B31*(C32*D33-D32*C33)-C31*(B32*D33-D32*B33)+D31*(B32*C33-C32*B33)
A36: k = −M⁻¹·w (Cramer, para que el álgebra quede a la vista)
A37: k1 | B37: =(-B16*(C32*D33-D32*C33) - C31*(-B17*D33+D32*B18) + D31*(-B17*C33+C32*B18))/$B$35
A38: k2 | B38: =(B31*(-B17*D33+D32*B18) + B16*(B32*D33-D32*B33) + D31*(-B32*B18+B17*B33))/$B$35
A39: k3 | B39: =(B31*(-C32*B18+B17*C33) - C31*(-B32*B18+B17*B33) - B16*(B32*C33-C32*B33))/$B$35
A41: CORRECCIONES v (ángulos en segundos · distancias en metros)
A42: v | B42: =B28*(B23*$B$37+B24*$B$38+B25*$B$39) | C42: =C28*(C23*$B$37+C24*$B$38+C25*$B$39) | D42: =D28*(D23*$B$37+D24*$B$38+D25*$B$39) | E42: =E28*(E23*$B$37+E24*$B$38+E25*$B$39) | F42: =F28*(F23*$B$37+F24*$B$38+F25*$B$39) | G42: =G28*(G23*$B$37+G24*$B$38+G25*$B$39) | H42: =H28*(H23*$B$37+H24*$B$38+H25*$B$39) | I42: =I28*(I23*$B$37+I24*$B$38+I25*$B$39) | ... K42: =K28*(K23*$B$37+K24*$B$38+K25*$B$39)
A44: RESULTADO AJUSTADO
A45: Punto | B45: Áng. ajust. (°) | C45: Azimut ajust. (°) | D45: Dist. ajust. (m) | E45: ΔN | F45: ΔE | G45: Norte | H45: Este
A46: Famarena_5 (partida) | G46: ='POLIGONAL MINIMOS'!K15 | H46: ='POLIGONAL MINIMOS'!L15
A47: D1 | B47: =B8+B$42/3600 | C47: =C8 | D47: =D8+G$42 | E47: =D47*COS(RADIANS(C47)) | F47: =D47*SIN(RADIANS(C47)) | G47: =G46+E47 | H47: =H46+F47
A48: D2 | B48: =B9+C$42/3600 | C48: =C9+SUM($B$42:B$42)/3600 | D48: =D9+H$42 | E48: =D48*COS(RADIANS(C48)) | F48: =D48*SIN(RADIANS(C48)) | G48: =G47+E48 | H48: =H47+F48
...
