Workbook

Sheet NIVELACION
C1: PUNTO | D1: V+ | E1: HI | F1: V- | G1: VI | H1: COTA | I1: DISTANCIA V+ | K1: DISTANCIA V-
C2: D1 | D2: 1.367 | H2: 3288.5
D3: 1.209 | E3: =H2+D3 -> 3289.709 | I3: =(D2-D4)*100 -> 31.5
D4: 1.052 | M4: =I3+K6 -> 60
C5: C 1 | D5: 3.416 | F5: 0.41
D6: 3.275 | E6: =H6+D6 -> 3292.716 | F6: 0.268 | H6: =E3-F6 -> 3289.441 | I6: =(D5-D7)*100 -> 28.1 | K6: =(F5-F7)*100 -> 28.5
D7: 3.135 | F7: 0.125 | M7: =I6+K9 -> 45.4
C8: C 2 | D8: 3.578 | F8: 0.31
D9: 3.469 | E9: =H9+D9 -> 3295.961 | F9: 0.224 | H9: =E6-F9 -> 3292.492 | I9: =(D8-D10)*100 -> 21.9 | K9: =(F8-F10)*100 -> 17.3
D10: 3.359 | F10: 0.137 | M10: =I9+K12 -> 33.6
C11: C 3 | D11: 4.08 | F11: 0.15
D12: 3.952 | E12: =H12+D12 -> 3299.821 | F12: 0.092 | H12: =E9-F12 -> 3295.869 | I12: =(D11-D13)*100 -> 25.5 | K12: =(F11-F13)*100 -> 11.7
D13: 3.825 | F13: 0.033 | M13: =I12+K15 -> 25.5
C14: AUX1 | G14: 0.271
G15: 0.194 | H15: =E12-G15 -> 3299.627
G16: 0.116 | M16: =I15+K18 -> 15.1
C17: C 4 | D17: 3.411 | F17: 0.319
D18: 3.314 | E18: =H18+D18 -> 3302.891 | F18: 0.244 | H18: =E12-F18 -> 3299.577 | I18: =(D17-D19)*100 -> 19.6 | K18: =(F17-F19)*100 -> 15.1
D19: 3.215 | F19: 0.168 | M19: =I18+K21 -> 36.2
C20: C 5 | D20: 3.104 | F20: 0.207
D21: 3.013 | E21: =H21+D21 -> 3305.78 | F21: 0.124 | H21: =E18-F21 -> 3302.767 | I21: =(D20-D22)*100 -> 18.1 | K21: =(F20-F22)*100 -> 16.6
D22: 2.923 | F22: 0.041 | M22: =I21+K24 -> 33.6
C23: C 6 | D23: 3.665 | F23: 0.222
D24: 3.549 | E24: =H24+D24 -> 3309.184 | F24: 0.145 | H24: =E21-F24 -> 3305.635 | I24: =(D23-D25)*100 -> 23.1 | K24: =(F23-F25)*100 -> 15.5
D25: 3.434 | F25: 0.067 | M25: =I24+K27 -> 38
C26: C 7 | D26: 3.281 | F26: 0.206
D27: 3.16 | E27: =H27+D27 -> 3312.212 | F27: 0.132 | H27: =E24-F27 -> 3309.052 | I27: =(D26-D28)*100 -> 24.2 | K27: =(F26-F28)*100 -> 14.9
D28: 3.039 | F28: 0.057 | M28: =I27+K30 -> 32.6
C29: D3 | D29: 2.468 | F29: 0.912
D30: 2.395 | E30: =H30+D30 -> 3313.737 | F30: 0.87 | H30: =E27-F30 -> 3311.342 | I30: =(D29-D31)*100 -> 14.7 | K30: =(F29-F31)*100 -> 8.4
D31: 2.321 | F31: 0.828 | M31: =I30+K33 -> 36.5
C32: C 8 | D32: 2.409 | F32: 0.304
D33: 2.349 | E33: =H33+D33 -> 3315.891 | F33: 0.195 | H33: =E30-F33 -> 3313.542 | I33: =(D32-D34)*100 -> 12.1 | K33: =(F32-F34)*100 -> 21.8
D34: 2.288 | F34: 0.086 | M34: =I33+K36 -> 27.8
C35: D4 | F35: 0.886
F36: 0.808 | H36: =E33-F36 -> 3315.083 | K36: =(F35-F37)*100 -> 15.7
F37: 0.729
D42: =D3+D6+D9+D12+D18+D21+D24+D27+D30+D33 -> 29.685 | F42: =F6+F9+F12+F18+F21+F24+F27+F30+F33+F36 -> 3.102 | L42: Distancia total | M42: =SUM(M4:M34) -> 384.3
D46: =H2-H36 -> -26.583 | F46: =D42-F42 -> 26.583 | G46: =F46+D46 -> 3.6948222e-13

Sheet CONTRANIVELACION
C1: PUNTO | D1: V+ | E1: HI | F1: V- | G1: VI | H1: COTA | I1: DISTANCIA V+ | J1: DISTANCIA V- | L1: Correccion | M1: Cotas finales a 3 CIFRAS DECIMAL
C2: D4 | D2: 0.937
D3: 0.865 | E3: =H3+D3 -> 3315.948 | H3: 3315.083 | I3: =(D2-D4)*100 -> 14.3 | L3: =H3+$O$4 -> 3315.0835 | M3: =L3 -> 3315.0835 | N3: ERROR | O3: =NIVELACION!H2-CONTRANIVELACION!H36 -> 0.005 | P3: =H3-NIVELACION!H36 -> 0
D4: 0.794 | K4: =SUM(I3+J6) -> 27.8 | N4: COMPENSACION | O4: =O3/11 -> 0.00045454545
C5: C 8 | D5: 0.878 | F5: 2.474 | N5: Error Cierre Orden 4 | O5: =IF(ABS(O3)<=K47,"CUMPLE","NO CUMPLE") -> CUMPLE
D6: 0.802 | E6: =H6+D6 -> 3314.343 | F6: 2.407 | H6: =E3-F6 -> 3313.541 | I6: =(D5-D7)*100 -> 15.2 | J6: =(F5-F7)*100 -> 13.5 | L6: =H6+$O$4 -> 3313.5415 | M6: =L6 -> 3313.5415 | P6: =H6-NIVELACION!H33 -> -0.001
D7: 0.726 | F7: 2.339 | K7: =SUM(I6+J9) -> 37.8
C8: D3 | D8: 0.605 | F8: 3.116
D9: 0.531 | E9: =H9+D9 -> 3311.871 | F9: 3.003 | H9: =E6-F9 -> 3311.34 | I9: =(D8-D10)*100 -> 14.8 | J9: =(F8-F10)*100 -> 22.6 | L9: =H9+$O$4 -> 3311.3405 | M9: =L9 -> 3311.3405 | P9: =H9-NIVELACION!H30 -> -0.002
D10: 0.457 | F10: 2.89 | K10: =SUM(I9+J12) -> 32.9
C11: C 7 | D11: 0.177 | F11: 2.912
D12: 0.092 | E12: =H12+D12 -> 3309.142 | F12: 2.821 | H12: =E9-F12 -> 3309.05 | I12: =(D11-D13)*100 -> 17 | J12: =(F11-F13)*100 -> 18.1 | L12: =H12+$O$4 -> 3309.0505 | M12: =L12 -> 3309.0505 | P12: =H12-NIVELACION!H27 -> -0.002
D13: 0.007 | F13: 2.731 | K13: =SUM(I12+J15) -> 37.9
B14: 0.17 | C14: C 6 | D14: 0.17 | F14: 3.614
B15: 0.083 | D15: 0.083 | E15: =H15+D15 -> 3305.715 | F15: 3.51 | H15: =E12-F15 -> 3305.632 | I15: =(B14-B16)*100 -> 25.7 | J15: =(F14-F16)*100 -> 20.9 | L15: =H15+$O$4 -> 3305.6325 | M15: =L15 -> 3305.6325 | P15: =H15-NIVELACION!H24 -> -0.003
B16: =B15-B14 -> -0.087 | D16: --- | F16: 3.405 | K16: =SUM(I15+J18) -> 41.9
C17: C 5 | D17: 0.35 | F17: 3.034
D18: 0.266 | E18: =H18+D18 -> 3303.028 | F18: 2.953 | H18: =E15-F18 -> 3302.762 | I18: =(D17-D19)*100 -> 16.8 | J18: =(F17-F19)*100 -> 16.2 | L18: =H18+$O$4 -> 3302.7625 | M18: =L18 -> 3302.7625 | P18: =H18-NIVELACION!H21 -> -0.005
D19: 0.182 | F19: 2.872 | K19: =SUM(I18+J21) -> 37
C20: C 4 | D20: 0.235 | F20: 3.557
D21: 0.157 | E21: =H21+D21 -> 3299.729 | F21: 3.456 | H21: =E18-F21 -> 3299.572 | I21: =(D20-D22)*100 -> 15.7 | J21: =(F20-F22)*100 -> 20.2 | L21: =H21+$O$4 -> 3299.5725 | M21: =L21 -> 3299.5725 | P21: =H21-NIVELACION!H18 -> -0.005
D22: 0.078 | F22: 3.355 | K22: =SUM(I21+J24) -> 15.7
C23: AUX 1 | G23: 0.188
G24: 0.107 | H24: =E21-G24 -> 3299.622 | I24: =(D23-D25)*100 -> 0 | J24: =(F23-F25)*100 -> 0 | L24: =H24+$O$4 -> 3299.6225 | M24: =L24 -> 3299.6225 | P24: =H24-NIVELACION!H15 -> -0.005
G25: 0.026
B26: 0.085 | C26: C 3 | D26: 0.085 | F26: 3.988
B27: 0.022 | D27: 0.022 | E27: =H27+D27 -> 3295.886 | F27: 3.865 | H27: =E21-F27 -> 3295.864 | I27: =(B26-B28)*100 -> 14.8 | J27: =(F26-F28)*100 -> 24.7 | L27: =H27+$O$4 -> 3295.8645 | M27: =L27 -> 3295.8645 | P27: =H27-NIVELACION!H12 -> -0.005
B28: =B27-B26 -> -0.063 | D28: --- | F28: 3.741 | K28: =SUM(I27+J30) -> 35.9
C29: C 2 | D29: 0.224 | F29: 3.505
D30: 0.134 | E30: =H30+D30 -> 3292.62 | F30: 3.4 | H30: =E27-F30 -> 3292.486 | I30: =(D29-D31)*100 -> 18 | J30: =(F29-F31)*100 -> 21.1 | L30: =H30+$O$4 -> 3292.4865 | M30: =L30 -> 3292.4865 | P30: =H30-NIVELACION!H9 -> -0.006
D31: 0.044 | F31: 3.294 | K31: =SUM(I30+J33) -> 45.5
C32: C 1 | D32: 0.554 | F32: 3.323
D33: 0.452 | E33: =H33+D33 -> 3289.886 | F33: 3.186 | H33: =E30-F33 -> 3289.434 | I33: =(D32-D34)*100 -> 20.4 | J33: =(F32-F34)*100 -> 27.5 | L33: =H33+$O$4 -> 3289.4345 | M33: =L33 -> 3289.4345 | P33: =H33-NIVELACION!H6 -> -0.007
D34: 0.35 | F34: 3.048 | K34: =SUM(I33+J36) -> 60.5
C35: D1 | F35: 1.591
F36: 1.391 | H36: =E33-F36 -> 3288.495 | J36: =(F35-F37)*100 -> 40.1 | L36: =H36+$O$4 -> 3288.4955 | M36: =L36 -> 3288.4955 | P36: =H36-NIVELACION!H2 -> -0.005
F37: 1.19
D40: =(D3+D6+D9+D12+D15+D18+D21+D27+D30+D33) -> 3.404 | F40: =F6+F9+F12+F15+F18+F21+F27+F30+F33+F36 -> 29.992
J42: DISTANCIA TOTAL | K42: =SUM(K4:K36) -> 372.9
D44: =H36-H3 -> -26.588 | E44: =F40-D40 -> 26.588 | F44: =E44+D44 -> -1.9539925e-13
...
